Traceback (most recent call last):
  File "/opt/hostedtoolcache/Python/3.9.21/x64/lib/python3.9/site-packages/jupyter_cache/executors/utils.py", line 58, in single_nb_execution
    executenb(
  File "/opt/hostedtoolcache/Python/3.9.21/x64/lib/python3.9/site-packages/nbclient/client.py", line 1319, in execute
    return NotebookClient(nb=nb, resources=resources, km=km, **kwargs).execute()
  File "/opt/hostedtoolcache/Python/3.9.21/x64/lib/python3.9/site-packages/jupyter_core/utils/__init__.py", line 165, in wrapped
    return loop.run_until_complete(inner)
  File "/opt/hostedtoolcache/Python/3.9.21/x64/lib/python3.9/asyncio/base_events.py", line 647, in run_until_complete
    return future.result()
  File "/opt/hostedtoolcache/Python/3.9.21/x64/lib/python3.9/site-packages/nbclient/client.py", line 709, in async_execute
    await self.async_execute_cell(
  File "/opt/hostedtoolcache/Python/3.9.21/x64/lib/python3.9/site-packages/nbclient/client.py", line 1062, in async_execute_cell
    await self._check_raise_for_error(cell, cell_index, exec_reply)
  File "/opt/hostedtoolcache/Python/3.9.21/x64/lib/python3.9/site-packages/nbclient/client.py", line 918, in _check_raise_for_error
    raise CellExecutionError.from_cell_and_msg(cell, exec_reply_content)
nbclient.exceptions.CellExecutionError: An error occurred while executing the following cell:
------------------
# Define category mapping
CATEGORY_MAP = {
    2: 'site-feedback'
    4: 'general',
    5: 'feature-request',
    6: 'bug-report',
    7: 'feedback',
    8: 'help',
    9: 'showcase',
    11: 'announcements'
}

# CATEGORIES = {
#     "site-feedback": 2,
#     "general": 4, # "discussion" on discourse
#     "feature-requests": 5,
#     "bug-report": 6,
#     "feedback": 7,
#     "how-to": 8,
#     "showcase": 9,
#     "announcements": 11,
# }
------------------


[0;36m  Cell [0;32mIn[2], line 4[0;36m[0m
[0;31m    4: 'general',[0m
[0m    ^[0m
[0;31mSyntaxError[0m[0;31m:[0m invalid syntax


